I'm sorry, but an uncaught exception occurred.

While running game code:
  File "game/rpy/plot/episode_01/chapter_01/01_01_00.rpy", line 2, in script
    unknown_future_I "……"
Exception: Sayer 'unknown_future_I' is not defined.

-- Full Traceback ------------------------------------------------------------

Full traceback:
  File "game/rpy/plot/episode_01/chapter_01/01_01_00.rpy", line 2, in script
    unknown_future_I "……"
  File "F:\renpy\renpy-8.1.1-sdk\renpy\ast.py", line 890, in execute
    who = eval_who(self.who, self.who_fast)
  File "F:\renpy\renpy-8.1.1-sdk\renpy\ast.py", line 783, in eval_who
    raise Exception("Sayer '%s' is not defined." % who)
Exception: Sayer 'unknown_future_I' is not defined.

Windows-10-10.0.19041 AMD64
Ren'Py 8.1.1.23060707
subject_51st 1.0
Tue Jul 11 21:18:18 2023
